/home/runner/workspace/analytics/data.py:7: FutureWarning: YF.download() has changed argument auto_adjust default to True
  data = yf.download(tickers, start=start, end=end)
[*********************100%***********************]  3 of 3 completed
Traceback (most recent call last):
  File "/home/runner/workspace/.pythonlibs/lib/python3.11/site-packages/pandas/core/indexes/base.py", line 3812, in get_loc
    return self._engine.get_loc(casted_key)
           ^^^^^^^^^^^^^^^^^^^^^^^^^^^^^^^^
  File "pandas/_libs/index.pyx", line 167, in pandas._libs.index.IndexEngine.get_loc
  File "pandas/_libs/index.pyx", line 196, in pandas._libs.index.IndexEngine.get_loc
  File "pandas/_libs/hashtable_class_helper.pxi", line 7088, in pandas._libs.hashtable.PyObjectHashTable.get_item
  File "pandas/_libs/hashtable_class_helper.pxi", line 7096, in pandas._libs.hashtable.PyObjectHashTable.get_item
KeyError: 'Adj Close'

The above exception was the direct cause of the following exception:

Traceback (most recent call last):
  File "/home/runner/workspace/main.py", line 11, in <module>
    prices = get_price_data(list(portfolio.keys()), start, end)
             ^^^^^^^^^^^^^^^^^^^^^^^^^^^^^^^^^^^^^^^^^^^^^^^^^^
  File "/home/runner/workspace/analytics/data.py", line 13, in get_price_data
    prices = data["Adj Close"]
             ~~~~^^^^^^^^^^^^^
  File "/home/runner/workspace/.pythonlibs/lib/python3.11/site-packages/pandas/core/frame.py", line 4106, in __getitem__
    return self._getitem_multilevel(key)
           ^^^^^^^^^^^^^^^^^^^^^^^^^^^^^
  File "/home/runner/workspace/.pythonlibs/lib/python3.11/site-packages/pandas/core/frame.py", line 4164, in _getitem_multilevel
    loc = self.columns.get_loc(key)
          ^^^^^^^^^^^^^^^^^^^^^^^^^
  File "/home/runner/workspace/.pythonlibs/lib/python3.11/site-packages/pandas/core/indexes/multi.py", line 3059, in get_loc
    loc = self._get_level_indexer(key, level=0)
          ^^^^^^^^^^^^^^^^^^^^^^^^^^^^^^^^^^^^^
  File "/home/runner/workspace/.pythonlibs/lib/python3.11/site-packages/pandas/core/indexes/multi.py", line 3410, in _get_level_indexer
    idx = self._get_loc_single_level_index(level_index, key)
          ^^^^^^^^^^^^^^^^^^^^^^^^^^^^^^^^^^^^^^^^^^^^^^^^^^
  File "/home/runner/workspace/.pythonlibs/lib/python3.11/site-packages/pandas/core/indexes/multi.py", line 2999, in _get_loc_single_level_index
    return level_index.get_loc(key)
           ^^^^^^^^^^^^^^^^^^^^^^^^
  File "/home/runner/workspace/.pythonlibs/lib/python3.11/site-packages/pandas/core/indexes/base.py", line 3819, in get_loc
    raise KeyError(key) from err
KeyError: 'Adj Close'
